<mujoco model="rope">
  <include file="./common/visual.xml"/>
  <include file="./common/skybox.xml"/>
  <include file="./common/materials.xml"/>

  <option timestep="0.002" density="3000">
    <flag contact="disable"/>
  </option>


  <default class="main">
    <geom rgba="1 0 0 1"/>
    <default class="sub">
        <geom rgba="0 1 0 1"/>
    </default>
  </default>

  <worldbody>
    <light cutoff="100" diffuse="1 1 1" dir="-0 0 -1" directional="true" exponent="1" pos="0 0 0.0" specular=".1 .1 .1"/>

    <geom rgba="0.1 0.1 .1 1." conaffinity="1" density='0.' contype="1" condim="1" name="table" pos="0 0.0 0." size="2.8 2.8 0.1" type="plane" />
    <!--  ================= SWIMMER ================= /-->
    <body name="rope" pos="0 0 1">
        <freejoint/>
        <composite type="rope" count="21 1 1" spacing="0.04" offset="0 0 2">
            <joint kind="main" damping="0.005" />
            <geom type="capsule" size=".01 .015" rgba=".8 .2 .1 1"/>
        </composite>
    </body>
    <body name="torso" pos="0 0 0">
      <geom density="1000" fromto="1.5 0 0 0.5 0 0" size="0.1" type="capsule"/>
      <joint axis="1 0 0" name="slider1" pos="0 0 0" type="slide"/>
      <joint axis="0 1 0" name="slider2" pos="0 0 0" type="slide"/>
      <joint axis="0 0 1" name="rot" pos="0 0 0" type="hinge"/>
      <body name="mid" pos="0.5 0 0">
        <geom density="1000" fromto="0 0 0 -1 0 0" size="0.1" type="capsule"/>
        <joint axis="0 0 1" limited="true" name="rot2" pos="0 0 0" range="-100 100" type="hinge"/>
        <body name="back" pos="-1 0 0">
          <geom density="1000" fromto="0 0 0 -1 0 0" size="0.1" type="capsule"/>
          <joint axis="0 0 1" limited="true" name="rot3" pos="0 0 0" range="-100 100" type="hinge"/>
        </body>
      </body>
    </body>
  </worldbody>

  <actuator>
    <motor ctrllimited="true" ctrlrange="-1 1" gear="150.0" joint="rot2"/>
    <motor ctrllimited="true" ctrlrange="-1 1" gear="150.0" joint="rot3"/>
  </actuator>


</mujoco>
<!--  <default>-->
<!--    <default class="swimmer">-->
<!--      <joint type="hinge" pos="0 -.05 0" axis="0 0 1" limited="true" solreflimit=".05 1" solimplimit="0 .8 .1" armature="1e-6"/>-->
<!--      <default class="inertial">-->
<!--        <geom type="box" size=".001 .05 .01" rgba="0 0 0 0" mass=".01"/>-->
<!--      </default>-->
<!--      <default class="visual">-->
<!--        <geom type="capsule" size=".01" fromto="0 -.05 0 0 .05 0" material="self" mass="0"/>-->
<!--      </default>-->
<!--      <site size=".01" rgba="0 0 0 0"/>-->
<!--    </default>-->
<!--    <default class="free">-->
<!--      <joint limited="false" stiffness="0" armature="0"/>-->
<!--    </default>-->
<!--    <motor gear="5e-4" ctrllimited="true" ctrlrange="-1 1"/>-->
<!--  </default>-->

<!--  <worldbody>-->
<!--    <geom name="ground" type="plane" size="2 2 0.1" material="grid"/>-->
<!--    <body name="head" pos="0 0 .05" childclass="swimmer">-->
<!--      <light name="light_1" diffuse=".8 .8 .8" pos="0 0 1.5"/>-->
<!--      <geom name="head" type="ellipsoid" size=".02 .04 .017" pos="0 -.022 0"  material="self" mass="0"/>-->
<!--      <geom name="nose" type="sphere" pos="0 -.06 0" size=".004" material="effector" mass="0"/>-->
<!--      <geom name="eyes" type="capsule" fromto="-.006 -.054 .005 .006 -.054 .005" size=".004" material="eye" mass="0"/>-->
<!--      <camera name="tracking1" pos="0 -.2 .5" xyaxes="1 0 0 0 1 1" mode="trackcom" fovy="60"/>-->
<!--      <camera name="tracking2" pos="-.9 .5 .15" xyaxes="0 -1 0 .3 0 1" mode="trackcom" fovy="60"/>-->
<!--      <camera name="eyes" pos="0 -.058 .005" xyaxes="-1 0 0 0 0 1"/>-->
<!--      <joint name="rootx" class="free" type="slide" axis="1 0 0" pos="0 -.05 0"/>-->
<!--      <joint name="rooty" class="free" type="slide" axis="0 1 0" pos="0 -.05 0"/>-->
<!--      <joint name="rootz" class="free" type="hinge" axis="0 0 1" pos="0 -.05 0"/>-->
<!--      <geom name="inertial" class="inertial"/>-->
<!--      <geom name="visual" class="visual"/>-->
<!--      <site name="head"/>-->
<!--    </body>-->
<!--    <geom name="target" type="sphere" pos="1 1 .05" size=".1" material="target"/>-->
<!--    <light name="target_light" diffuse="1 1 1" pos="1 1 1.5"/>-->
<!--  </worldbody>-->

<!--  <sensor>-->
<!--    <framepos name="nose_pos" objtype="geom" objname="nose"/>-->
<!--    <framepos name="target_pos" objtype="geom" objname="target"/>-->
<!--    <framexaxis name="head_xaxis" objtype="xbody" objname="head"/>-->
<!--    <frameyaxis name="head_yaxis" objtype="xbody" objname="head"/>-->
<!--    <velocimeter name="head_vel" site="head"/>-->
<!--    <gyro name="head_gyro" site="head"/>-->
<!--  </sensor>-->





<!--<mujoco>-->
<!--    <default class="main">-->
<!--        <geom rgba="1 0 0 1"/>-->
<!--        <default class="sub">-->
<!--            <geom rgba="0 1 0 1"/>-->
<!--        </default>-->
<!--    </default>-->
<!--  <worldbody>-->
<!--    <light cutoff="100" diffuse="1 1 1" dir="-0 0 -1" directional="true" exponent="1" pos="0 0 0.0" specular=".1 .1 .1"/>-->

<!--    <geom rgba="0.1 0.1 .1 1." conaffinity="1" density='0.' contype="1" condim="1" name="table" pos="0 0.0 0." size="2.8 2.8 0.1" type="plane" />-->
<!--    &lt;!&ndash;  ================= SWIMMER ================= /&ndash;&gt;-->
<!--    <body name="B10" pos="0 0 1">-->
<!--        <freejoint/>-->
<!--        <composite type="rope" count="21 1 1" spacing="0.04" offset="0 0 2">-->
<!--            <joint kind="main" damping="0.005" />-->
<!--            <geom type="capsule" size=".01 .015" rgba=".8 .2 .1 1"/>-->
<!--        </composite>-->
<!--    </body>-->
<!--    <body name="torso" pos="0 0 0">-->
<!--      <geom density="1000" fromto="1.5 0 0 0.5 0 0" size="0.1" type="capsule"/>-->
<!--      <joint axis="1 0 0" name="slider1" pos="0 0 0" type="slide"/>-->
<!--      <joint axis="0 1 0" name="slider2" pos="0 0 0" type="slide"/>-->
<!--      <joint axis="0 0 1" name="rot" pos="0 0 0" type="hinge"/>-->
<!--      <body name="mid" pos="0.5 0 0">-->
<!--        <geom density="1000" fromto="0 0 0 -1 0 0" size="0.1" type="capsule"/>-->
<!--        <joint axis="0 0 1" limited="true" name="rot2" pos="0 0 0" range="-100 100" type="hinge"/>-->
<!--        <body name="back" pos="-1 0 0">-->
<!--          <geom density="1000" fromto="0 0 0 -1 0 0" size="0.1" type="capsule"/>-->
<!--          <joint axis="0 0 1" limited="true" name="rot3" pos="0 0 0" range="-100 100" type="hinge"/>-->
<!--        </body>-->
<!--      </body>-->
<!--    </body>-->
<!--  </worldbody>-->
<!--  <actuator>-->
<!--    <motor ctrllimited="true" ctrlrange="-1 1" gear="150.0" joint="rot2"/>-->
<!--    <motor ctrllimited="true" ctrlrange="-1 1" gear="150.0" joint="rot3"/>-->
<!--  </actuator>-->
<!--    <worldbody>-->

<!--        <light cutoff="100" diffuse="1 1 1" dir="-0 0 -1" directional="true" exponent="1" pos="0 0 0.0" specular=".1 .1 .1"/>-->

<!--        <geom rgba="0.1 0.1 .1 1." conaffinity="1" density='0.' contype="1" condim="1" name="table" pos="0 0.0 0." size="2.8 2.8 0.1" type="plane" />-->

<!--        <body name="B10" pos="0 0 1">-->
<!--            <freejoint/>-->
<!--            <composite type="rope" count="21 1 1" spacing="0.04" offset="0 0 2">-->
<!--                <joint kind="main" damping="0.005" />-->
<!--                <geom type="capsule" size=".01 .015" rgba=".8 .2 .1 1"/>-->
<!--            </composite>-->
<!--        </body>-->
<!--        <body name="back" pos="-1 0 0">-->
<!--          <geom density="1000" fromto="0 0 0 -1 0 0" size="0.1" type="capsule"/>-->
<!--          <joint axis="0 0 1" limited="true" name="rot3" pos="0 0 0" range="-100 100" type="hinge"/>-->
<!--        </body>-->
<!--    </worldbody>-->
<!--    <actuator>-->
<!--        <general joint="rot3"  ctrlrange="-1 1" ctrllimited="True"/>-->
<!--    </actuator>-->
<!--</mujoco>-->
<!--    # rope object-->

<!--    </body>-->
<!--            <composite type="grid" count="11 9 1" spacing="0.2" offset="0. 0. 0">-->
<!--            <skin texcoord="true" material="mathammock" inflate="0.01" subgrid="3"/>-->
<!--            <pin coord="0 0"/>-->
<!--            <pin coord="10 0"/>-->
<!--            <pin coord="0 8"/>-->
<!--            <pin coord="10 8"/>-->
<!--            <geom size=".095"/>-->
<!--            <joint kind="main" damping="10"/>-->
<!--        </composite>-->

<!--</mujoco>-->